<testsuite name="Mocha Tests" tests="2" failures="0" errors="2" skipped="0" timestamp="Sun, 01 Dec 2019 13:50:31 GMT" time="2.119">
<testcase classname="Sample task tests" name="should success with simple inputs" time="0.114"><failure>should have succeeded

      + expected - actual

      -false
      +true
      
AssertionError [ERR_ASSERTION]: should have succeeded
    at Context.&#x3C;anonymous&#x3E; (tests/suite.js:24:16)
    at processImmediate (internal/timers.js:439:21)</failure></testcase>
<testcase classname="Sample task tests" name="it should fail if tool returns 1" time="2.002"><failure>Timeout of 2000ms exceeded. For async tests and hooks, ensure &#x22;done()&#x22; is called; if returning a Promise, ensure it resolves. (/Users/lturmel/Documents/GitHub/AzureDNSZoneExtensions/aRecordManager/tests/suite.js)
Error: Timeout of 2000ms exceeded. For async tests and hooks, ensure &#x22;done()&#x22; is called; if returning a Promise, ensure it resolves. (/Users/lturmel/Documents/GitHub/AzureDNSZoneExtensions/aRecordManager/tests/suite.js)
    at listOnTimeout (internal/timers.js:531:17)
    at processTimers (internal/timers.js:475:7)</failure></testcase>
</testsuite>
